Workbook

Sheet Input sheet
C1: Input cell | E1: Calculated cell
A3: Date of valuation | B3: 44592 | C3: Important: Before you run this spreadsheet, go into preferences in Excel and check under Calculation options
A4: Company name | B4: TEST (StockInsight test ticker) | C4: There should be a check against the iteration box. If there is not, you will get circular reasoning errors.
A5: Numbers from your base year below ( in consistent units, i.e., if you enter numbers in millions, stay with millions all the way through, including on share count.
A6: If you don't understand an input, turn on comemnts and you should see my suggestions on that input.
A7: Country of incorporation | B7: United States | F7: If you want a guide through this spreadsheet, try this YouTube video that takes you through each input cell: https://youtu.be/kyKfJ_7-mdg?si=FIeHhnLH2_2brag3
A8: Industry (US) | B8: Advertising
A9: Industry (Global) | B9: Advertising
B10: Most Recent 12 months | C10: Last 10K before LTM | D10: Years since last 10K
A11: Revenues | B11: 10000000 | C11: 9000000 | D11: 1
A12: Operating income or EBIT | B12: 1000000 | C12: 900000
A13: Interest expense | B13: 10000000 | C13: 9000000
A14: Book value of equity | B14: 10000000 | C14: 9000000
A15: Book value of debt | B15: 10000000 | C15: 9000000
A16: Do you have R&D expenses to capitalize? | B16: No | C16: If you want to capitalize R&D, you have to input the numbers into the R&D worksheet.
A17: Do you have operating lease commitments? | B17: No | C17: If you lease or other contractual commitments that have not been converteed to debt already, say yes to this option and do the conversion.
A18: Cash and Marketable Securities | B18: 10000000 | C18: 9000000
A19: Cross holdings and other non-operating assets | B19: 0 | C19: 0
A20: Minority interests | B20: 0 | C20: 0
A21: Number of shares outstanding = | B21: 10000000 | E21: Computed numbers: Here is what your company's numbers look like, relative to industry.
A22: Current stock price = | B22: 100 | E22: If you are not working in US dollars, you should add the inflation differential to the industry averages.
A23: Effective tax rate = | B23: 0.175 | J23: Industry (US) | K23: Industry (Global) | L23: Global Distribution Stats
A24: Marginal tax rate = | B24: 0.25 | I24: Company | J24: Average | K24: Average | L24: 1st Quartile | M24: Median | N24: 3rd Quartile
A25: The value drivers below: | E25: Revenue growth in the most recent year = | I25: =IF(C11>0,(B11/C11)^(1/D11)-1, "NA") | J25: =VLOOKUP(B8,'Industry Averages(US)'!A2:S95,3) | K25: =VLOOKUP(B9,'Industry Averages (Global)'!A2:N95,3) | L25: =VLOOKUP($B$9,'Input Stat Distributioons'!$A$3:$T$96,3,FALSE) | M25: =VLOOKUP($B$9,'Input Stat Distributioons'!$A$3:$T$96,4,FALSE) | N25: =VLOOKUP($B$9,'Input Stat Distributioons'!$A$3:$T$96,5,FALSE)
A26: Revenue growth rate for next year | B26: 0.1 | C26: Growth Lever - Next year | E26: Pre-tax operating margin in the most recent year = | I26: ='Valuation output'!B4 | J26: =VLOOKUP(B8,'Industry Averages(US)'!A2:AA95,4) | K26: =VLOOKUP(B9,'Industry Averages (Global)'!A2:N95,4) | L26: =VLOOKUP($B$9,'Input Stat Distributioons'!$A$3:$T$96,6,FALSE) | M26: =VLOOKUP($B$9,'Input Stat Distributioons'!$A$3:$T$96,7,FALSE) | N26: =VLOOKUP($B$9,'Input Stat Distributioons'!$A$3:$T$96,8,FALSE)
A27: Operating Margin for next year | B27: 0.1 | C27: Profitability Lever - Next year | E27: Sales to capital ratio in most recent year = | I27: =B11/'Valuation output'!B39 | J27: =VLOOKUP(B8,'Industry Averages(US)'!A2:S95,14) | K27: =VLOOKUP(B9,'Industry Averages (Global)'!A2:N95,14) | L27: =VLOOKUP($B$9,'Input Stat Distributioons'!$A$3:$T$96,9,FALSE) | M27: =VLOOKUP($B$9,'Input Stat Distributioons'!$A$3:$T$96,10,FALSE) | N27: =VLOOKUP($B$9,'Input Stat Distributioons'!$A$3:$T$96,11,FALSE)
A28: Compounded annual revenue growth rate - years 2-5 = | B28: 0.1 | C28: Growth Lever - Long term | E28: Marginal sales to capital ratio = | I28: =IF(('Input sheet'!B11-'Input sheet'!C11)/(('Input sheet'!B14+'Input sheet'!B15-'Input sheet'!B18)-('Input sheet'!C14+'Input sheet'!C15-'Input sheet'!C18))>0,('Input sheet'!B11-'Input sheet'!C11)/(('Input sheet'!B14+'Input sheet'!B15-'Input sheet'!B18)-('Input sheet'!C14+'Input sheet'!C15-'Input sheet'!C18)),"NA")
A29: Target pre-tax operating margin = | B29: 0.1 | C29: Profitability Lever - Long term | E29: Return on invested capital in most recent year= | I29: ='Valuation output'!B7/'Valuation output'!B39 | J29: =VLOOKUP(B8,'Industry Averages(US)'!A2:S95,5) | K29: =VLOOKUP(B9,'Industry Averages (Global)'!A2:N95,5)
A30: Year of convergence for margin | B30: 5 | C30: Speed of convergence level | E30: Standard deviation in stock prices = | J30: =VLOOKUP(B8,'Industry Averages(US)'!A2:S95,10) | K30: =VLOOKUP(B8,'Industry Averages (Global)'!A2:Z95,10)
A31: Sales to capital ratio (for years 1-5) | B31: 2 | C31: Efficency of Growth Lever (first 5 years) | E31: Cost of capital = | I31: =B35 | J31: =VLOOKUP(B8,'Industry Averages(US)'!A2:S95,13) | K31: =VLOOKUP(B8,'Industry Averages (Global)'!A2:Z95,13) | L31: =VLOOKUP($B$9,'Input Stat Distributioons'!$A$3:$T$96,12,FALSE) | M31: =VLOOKUP($B$9,'Input Stat Distributioons'!$A$3:$T$96,13,FALSE) | N31: =VLOOKUP($B$9,'Input Stat Distributioons'!$A$3:$T$96,14,FALSE)
A32: Sales to capital ratio (for years 6-10) | B32: 2 | C32: Efficency of Growth Lever (years 6-10)
A33: Market numbers | E33: Valuation Output Feedback (for you to use to fine tune your inputs, if you want)
A34: Riskfree rate | B34: 0.04 | E34: Revenues in year 10, based on your revenue growth = | J34: ='Valuation output'!M3
A35: Initial cost of capital = | B35: ='Cost of capital worksheet'!B13 | C35: Do not input. Go to cost of capital sheet. | E35: Pre-tax Operating Income in year 10, based on your operating margin = | J35: ='Valuation output'!M5
A36: Other inputs | E36: Return on invested capital in year 10, based on your sales/capital ratio = | J36: ='Valuation output'!L40
A37: Do you have employee options outstanding? | B37: No | E37: Check the Diagnostics worksheet for more details.
A38: Number of options outstanding = | B38: 7.72
A39: Average strike price = | B39: 1.29
A40: Average maturity = | B40: 7
A41: Standard deviation on stock price = | B41: 0.45
...

Sheet Valuation output
B1: Base year | C1: 1 | D1: 2 | E1: 3 | F1: 4 | G1: 5 | H1: 6 | I1: 7 | J1: 8 | K1: 9 | L1: 10 | M1: Terminal year
A2: Revenue growth rate | C2: ='Input sheet'!B26 | D2: ='Input sheet'!B28 | E2: =D2 | F2: =E2 | G2: =F2 | H2: =G2-((G2-$M$2)/5) | I2: =G2-((G2-$M$2)/5)*2 | J2: =G2-((G2-$M$2)/5)*3 | K2: =G2-((G2-$M$2)/5)*4 | L2: =G2-((G2-$M$2)/5)*5 | M2: =IF('Input sheet'!B67="Yes",'Input sheet'!B68,IF('Input sheet'!B64="Yes",'Input sheet'!B65,'Input sheet'!B34))
A3: Revenues | B3: ='Input sheet'!B11 | C3: =B3*(1+C2) | D3: =C3*(1+D2) | E3: =D3*(1+E2) | F3: =E3*(1+F2) | G3: =F3*(1+G2) | H3: =G3*(1+H2) | I3: =H3*(1+I2) | J3: =I3*(1+J2) | ... M3: =L3*(1+M2)
A4: EBIT (Operating) margin | B4: =B5/B3 | C4: ='Input sheet'!B27 | D4: =IF(D1>'Input sheet'!$B$30,'Input sheet'!$B$29,'Input sheet'!$B$29-(('Input sheet'!$B$29-$C$4)/'Input sheet'!$B$30)*('Input sheet'!$B$30-D1)) | E4: =IF(E1>'Input sheet'!$B$30,'Input sheet'!$B$29,'Input sheet'!$B$29-(('Input sheet'!$B$29-$C$4)/'Input sheet'!$B$30)*('Input sheet'!$B$30-E1)) | F4: =IF(F1>'Input sheet'!$B$30,'Input sheet'!$B$29,'Input sheet'!$B$29-(('Input sheet'!$B$29-$C$4)/'Input sheet'!$B$30)*('Input sheet'!$B$30-F1)) | G4: =IF(G1>'Input sheet'!$B$30,'Input sheet'!$B$29,'Input sheet'!$B$29-(('Input sheet'!$B$29-$C$4)/'Input sheet'!$B$30)*('Input sheet'!$B$30-G1)) | H4: =IF(H1>'Input sheet'!$B$30,'Input sheet'!$B$29,'Input sheet'!$B$29-(('Input sheet'!$B$29-$C$4)/'Input sheet'!$B$30)*('Input sheet'!$B$30-H1)) | I4: =IF(I1>'Input sheet'!$B$30,'Input sheet'!$B$29,'Input sheet'!$B$29-(('Input sheet'!$B$29-$C$4)/'Input sheet'!$B$30)*('Input sheet'!$B$30-I1)) | J4: =IF(J1>'Input sheet'!$B$30,'Input sheet'!$B$29,'Input sheet'!$B$29-(('Input sheet'!$B$29-$C$4)/'Input sheet'!$B$30)*('Input sheet'!$B$30-J1)) | K4: =IF(K1>'Input sheet'!$B$30,'Input sheet'!$B$29,'Input sheet'!$B$29-(('Input sheet'!$B$29-$C$4)/'Input sheet'!$B$30)*('Input sheet'!$B$30-K1)) | L4: =IF(L1>'Input sheet'!$B$30,'Input sheet'!$B$29,'Input sheet'!$B$29-(('Input sheet'!$B$29-$C$4)/'Input sheet'!$B$30)*('Input sheet'!$B$30-L1)) | M4: =L4
A5: EBIT (Operating income) | B5: =IF('Input sheet'!B17="Yes",IF('Input sheet'!B16="Yes",'Input sheet'!B12+'Operating lease converter'!F32+'R& D converter'!D39,'Input sheet'!B12+'Operating lease converter'!F32),IF('Input sheet'!B16="Yes",'Input sheet'!B12+'R& D converter'!D39,'Input sheet'!B12)) | C5: =C4*C3 | D5: =D4*D3 | E5: =E4*E3 | F5: =F4*F3 | G5: =G4*G3 | H5: =H4*H3 | I5: =I4*I3 | J5: =J4*J3 | ... M5: =M4*M3 | N5: =M5-B5
A6: Tax rate | B6: ='Input sheet'!B23 | C6: =B6 | D6: =C6 | E6: =D6 | F6: =E6 | G6: =F6 | H6: =G6+($M$6-$G$6)/5 | I6: =H6+($M$6-$G$6)/5 | J6: =I6+($M$6-$G$6)/5 | K6: =J6+($M$6-$G$6)/5 | L6: =K6+($M$6-$G$6)/5 | M6: =IF('Input sheet'!B59="Yes",'Input sheet'!B23,'Input sheet'!B24)
A7: EBIT(1-t) | B7: =IF(B5>0,B5*(1-B6),B5) | C7: =IF(C5>0,IF(C5<B10,C5,C5-(C5-B10)*C6),C5) | D7: =IF(D5>0,IF(D5<C10,D5,D5-(D5-C10)*D6),D5) | E7: =IF(E5>0,IF(E5<D10,E5,E5-(E5-D10)*E6),E5) | F7: =IF(F5>0,IF(F5<E10,F5,F5-(F5-E10)*F6),F5) | G7: =IF(G5>0,IF(G5<F10,G5,G5-(G5-F10)*G6),G5) | H7: =IF(H5>0,IF(H5<G10,H5,H5-(H5-G10)*H6),H5) | I7: =IF(I5>0,IF(I5<H10,I5,I5-(I5-H10)*I6),I5) | J7: =IF(J5>0,IF(J5<I10,J5,J5-(J5-I10)*J6),J5) | ... L7: =IF(L5>0,IF(L5<K10,L5,L5-(L5-K10)*L6),L5) | M7: =M5*(1-M6)
A8: - Reinvestment | C8: =IF('Input sheet'!$B$56="No",(D3-C3)/C38,IF('Input sheet'!$B$57=0,(C3-B3)/C38,IF('Input sheet'!$B$57=2,(E3-D3)/C38,IF('Input sheet'!$B$57=3,(F3-E3)/C38,(D3-C3)/C38)))) | D8: =IF('Input sheet'!$B$56="No",(E3-D3)/D38,IF('Input sheet'!$B$57=0,(D3-C3)/D38,IF('Input sheet'!$B$57=2,(F3-E3)/D38,IF('Input sheet'!$B$57=3,(G3-F3)/D38,(E3-D3)/D38)))) | E8: =IF('Input sheet'!$B$56="No",(F3-E3)/E38,IF('Input sheet'!$B$57=0,(E3-D3)/E38,IF('Input sheet'!$B$57=2,(G3-F3)/E38,IF('Input sheet'!$B$57=3,(H3-G3)/E38,(F3-E3)/E38)))) | F8: =IF('Input sheet'!$B$56="No",(G3-F3)/F38,IF('Input sheet'!$B$57=0,(F3-E3)/F38,IF('Input sheet'!$B$57=2,(H3-G3)/F38,IF('Input sheet'!$B$57=3,(I3-H3)/F38,(G3-F3)/F38)))) | G8: =IF('Input sheet'!$B$56="No",(H3-G3)/G38,IF('Input sheet'!$B$57=0,(G3-F3)/G38,IF('Input sheet'!$B$57=2,(I3-H3)/G38,IF('Input sheet'!$B$57=3,(J3-I3)/G38,(H3-G3)/G38)))) | H8: =IF('Input sheet'!$B$56="No",(I3-H3)/H38,IF('Input sheet'!$B$57=0,(H3-G3)/H38,IF('Input sheet'!$B$57=2,(J3-I3)/H38,IF('Input sheet'!$B$57=3,(K3-J3)/H38,(I3-H3)/H38)))) | I8: =IF('Input sheet'!$B$56="No",(J3-I3)/I38,IF('Input sheet'!$B$57=0,(I3-H3)/I38,IF('Input sheet'!$B$57=2,(K3-J3)/I38,IF('Input sheet'!$B$57=3,(L3-K3)/I38,(J3-I3)/I38)))) | J8: =IF('Input sheet'!$B$56="No",(K3-J3)/J38,IF('Input sheet'!$B$57=0,(J3-I3)/J38,IF('Input sheet'!$B$57=2,(L3-K3)/J38,IF('Input sheet'!$B$57=3,(M3-L3)/J38,(K3-J3)/J38)))) | K8: =IF('Input sheet'!$B$56="No",(L3-K3)/K38,IF('Input sheet'!$B$57=0,(K3-J3)/K38,IF('Input sheet'!$B$57=2,L3*L2/K38,IF('Input sheet'!$B$57=3,M3*M2/K38,(L3-K3)/K38)))) | L8: =IF('Input sheet'!$B$56="No",(M3-L3)/L38,IF('Input sheet'!$B$57=0,(L3-K3)/L38,IF('Input sheet'!$B$57=2,M3*M2/L38,IF('Input sheet'!$B$57=3,K8*(1+M2),(M3-L3)/L38)))) | M8: =IF(M2>0,(M2/M40)*M7,0) | N8: =SUM(C8:M8)
A9: FCFF | C9: =C7-C8 | D9: =D7-D8 | E9: =E7-E8 | F9: =F7-F8 | G9: =G7-G8 | H9: =H7-H8 | I9: =I7-I8 | J9: =J7-J8 | ... M9: =M7-M8
A10: NOL | B10: =IF('Input sheet'!B61="Yes",'Input sheet'!B62,0) | C10: =IF(C5<0,B10-C5,IF(B10>C5,B10-C5,0)) | D10: =IF(D5<0,C10-D5,IF(C10>D5,C10-D5,0)) | E10: =IF(E5<0,D10-E5,IF(D10>E5,D10-E5,0)) | F10: =IF(F5<0,E10-F5,IF(E10>F5,E10-F5,0)) | G10: =IF(G5<0,F10-G5,IF(F10>G5,F10-G5,0)) | H10: =IF(H5<0,G10-H5,IF(G10>H5,G10-H5,0)) | I10: =IF(I5<0,H10-I5,IF(H10>I5,H10-I5,0)) | J10: =IF(J5<0,I10-J5,IF(I10>J5,I10-J5,0)) | ... M10: =IF(M5<0,L10-M5,IF(L10>M5,L10-M5,0))
A12: Cost of capital | C12: ='Input sheet'!B35 | D12: =C12 | E12: =D12 | F12: =E12 | G12: =F12 | H12: =G12-($G$12-$M$12)/5 | I12: =H12-($G$12-$M$12)/5 | J12: =I12-($G$12-$M$12)/5 | K12: =J12-($G$12-$M$12)/5 | L12: =K12-($G$12-$M$12)/5 | M12: =IF('Input sheet'!B45="Yes",'Input sheet'!B46,IF('Input sheet'!B64="Yes",'Input sheet'!B65+'Country equity risk premiums'!B1,'Input sheet'!B34+'Country equity risk premiums'!B1))
A13: Cumulated discount factor | C13: =1/(1+C12) | D13: =C13*(1/(1+D12)) | E13: =D13*(1/(1+E12)) | F13: =E13*(1/(1+F12)) | G13: =F13*(1/(1+G12)) | H13: =G13*(1/(1+H12)) | I13: =H13*(1/(1+I12)) | J13: =I13*(1/(1+J12)) | K13: =J13*(1/(1+K12)) | L13: =K13*(1/(1+L12))
A14: PV(FCFF) | C14: =C9*C13 | D14: =D9*D13 | E14: =E9*E13 | F14: =F9*F13 | G14: =G9*G13 | H14: =H9*H13 | I14: =I9*I13 | J14: =J9*J13 | ... L14: =L9*L13
A16: Terminal cash flow | B16: =M9
A17: Terminal cost of capital | B17: =M12
A18: Terminal value | B18: =B16/(B17-M2)
A19: PV(Terminal value) | B19: =B18*L13
A20: PV (CF over next 10 years) | B20: =SUM(C14:L14)
A21: Sum of PV | B21: =B19+B20
A22: Probability of failure = | B22: =IF('Input sheet'!B51="Yes",'Input sheet'!B52,0)
A23: Proceeds if firm fails = | B23: =IF('Input sheet'!B53="B",('Input sheet'!B14+'Input sheet'!B15)*'Input sheet'!B54,'Valuation output'!B21*'Input sheet'!B54)
A24: Value of operating assets = | B24: =B21*(1-B22)+B23*B22
A25: - Debt | B25: =IF('Input sheet'!B17="Yes",'Input sheet'!B15+'Operating lease converter'!C28,'Input sheet'!B15)
A26: - Minority interests | B26: ='Input sheet'!B20
A27: + Cash | B27: =IF('Input sheet'!B70="YES",'Input sheet'!B18-'Input sheet'!B71*('Input sheet'!B24-'Input sheet'!B72),'Input sheet'!B18) | D27: If you get Value Errors all over, it is usually because your option worksheet has gone haywire. The fix is very low tech. Go into the option value worksheet, and in cell B17 of that worksheet (adjusted S), enter any number (say 5) and then undo what you did. Voila!
A28: + Non-operating assets | B28: ='Input sheet'!B19
A29: Value of equity | B29: =B24-B25-B26+B27+B28
A30: - Value of options | B30: =IF('Input sheet'!B37="No",0,'Option value'!B29)
A31: Value of equity in common stock | B31: =B29-B30
A32: Number of shares | B32: ='Input sheet'!B21
A33: Estimated value /share | B33: =B31/B32
A34: Price | B34: ='Input sheet'!B22
A35: Price as % of value | B35: =B34/B33
A37: Implied variables | M37: After year 10
A38: Sales to capital ratio | C38: ='Input sheet'!B31 | D38: ='Input sheet'!B31 | E38: =D38 | F38: =E38 | G38: =F38 | H38: ='Input sheet'!B32 | I38: =H38 | J38: =I38 | K38: =J38 | L38: =K38
A39: Invested capital | B39: =IF('Input sheet'!B17="Yes",IF('Input sheet'!B16="Yes",'Input sheet'!B14+'Input sheet'!B15-'Input sheet'!B18+'Operating lease converter'!F33+'R& D converter'!D35,'Input sheet'!B14+'Input sheet'!B15-'Input sheet'!B18+'Operating lease converter'!F33),IF('Input sheet'!B16="Yes",'Input sheet'!B14+'Input sheet'!B15-'Input sheet'!B18+'R& D converter'!D35,'Input sheet'!B14+'Input sheet'!B15-'Input sheet'!B18)) | C39: =B39+C8 | D39: =C39+D8 | E39: =D39+E8 | F39: =E39+F8 | G39: =F39+G8 | H39: =G39+H8 | I39: =H39+I8 | J39: =I39+J8 | ... L39: =K39+L8
A40: ROIC | B40: =B7/B39 | C40: =C7/B39 | D40: =D7/C39 | E40: =E7/D39 | F40: =F7/E39 | G40: =G7/F39 | H40: =H7/G39 | I40: =I7/H39 | J40: =J7/I39 | ... L40: =L7/K39 | M40: =IF('Input sheet'!B48="Yes",'Input sheet'!B49,'Valuation output'!L12)

Sheet Stories to Numbers
A1: ='Input sheet'!B4 | G1: ='Input sheet'!B3
A2: The Disruption Platform Rolls on
A3: Amazon continues on its transformation from online retailer to disruption platform, willling to enter any business that it perceives as inefficiently run, and changing it. Along the way, it will invest large amounts of capital and wait for long periods to attain profitability. | H3: Tell your story about the company. Keep it focuses on the company's businesses and tie it into the three key levers of value: cash flows, growth and risk
A7: The Assumptions
B8: Base year | C8: Next year | D8: Years 2-5 | E8: Years 6-10 | F8: After year 10 | G8: Link to story
A9: Revenues (a) | B9: ='Valuation output'!B3 | C9: ='Input sheet'!B26 | D9: ='Input sheet'!B28 | E9: Changes to | F9: ='Valuation output'!M2 | G9: Disruption platform in multiple businesses | H9: Tie each assumption to the part of your story that relates to it.
A10: Operating margin (b) | B10: ='Valuation output'!B4 | C10: ='Input sheet'!B27 | D10: Moves to | E10: ='Valuation output'!G4 | F10: ='Valuation output'!M4 | G10: Margins improve, aided by cloud business & continued economies of scale.
A11: Tax rate | B11: ='Valuation output'!B6 | D11: =B11 | E11: Changes to | F11: ='Valuation output'!M6 | G11: Global/US marginal tax rate over time
A12: Sales to Capital (c ) | C12: ='Input sheet'!B31 | D12: ='Input sheet'!B31 | E12: ='Input sheet'!B32 | F12: ='Valuation output'!M2/'Valuation output'!M40 | G12: Maintained at Amazon's current level
A13: Return on capital | B13: ='Valuation output'!B40 | C13: Marginal ROIC = | D13: =Diagnostics!C27 | F13: ='Valuation output'!M40 | G13: Strong competitive edges
A14: Cost of capital (d) | D14: ='Valuation output'!C12 | F14: ='Valuation output'!M12 | G14: Cost of capital close to median company
A15: The Cash Flows
B16: Revenues | C16: Operating Margin | D16: EBIT | E16: EBIT (1-t) | F16: Reinvestment | G16: FCFF | H16: These are the numbers that come from your assumptions. The revenues over time reflect your revenue growth, the operating margins evolve towards your target margin and your tax rate will change, if you have set it to. The reinvestment is estimated using the sales to capital ratio for the first 10 years and based on a reinvestment rate in stable growth (g/ ROC).
A17: 1 | B17: ='Valuation output'!C3 | C17: ='Valuation output'!C4 | D17: =B17*C17 | E17: ='Valuation output'!C7 | F17: ='Valuation output'!C8 | G17: =E17-F17
A18: 2 | B18: ='Valuation output'!D3 | C18: ='Valuation output'!D4 | D18: =B18*C18 | E18: ='Valuation output'!D7 | F18: ='Valuation output'!D8 | G18: =E18-F18
A19: 3 | B19: ='Valuation output'!E3 | C19: ='Valuation output'!E4 | D19: =B19*C19 | E19: ='Valuation output'!E7 | F19: ='Valuation output'!E8 | G19: =E19-F19
A20: 4 | B20: ='Valuation output'!F3 | C20: ='Valuation output'!F4 | D20: =B20*C20 | E20: ='Valuation output'!F7 | F20: ='Valuation output'!F8 | G20: =E20-F20
A21: 5 | B21: ='Valuation output'!G3 | C21: ='Valuation output'!G4 | D21: =B21*C21 | E21: ='Valuation output'!G7 | F21: ='Valuation output'!G8 | G21: =E21-F21
A22: 6 | B22: ='Valuation output'!H3 | C22: ='Valuation output'!H4 | D22: =B22*C22 | E22: ='Valuation output'!H7 | F22: ='Valuation output'!H8 | G22: =E22-F22
A23: 7 | B23: ='Valuation output'!I3 | C23: ='Valuation output'!I4 | D23: =B23*C23 | E23: ='Valuation output'!I7 | F23: ='Valuation output'!I8 | G23: =E23-F23
A24: 8 | B24: ='Valuation output'!J3 | C24: ='Valuation output'!J4 | D24: =B24*C24 | E24: ='Valuation output'!J7 | F24: ='Valuation output'!J8 | G24: =E24-F24
A25: 9 | B25: ='Valuation output'!K3 | C25: ='Valuation output'!K4 | D25: =B25*C25 | E25: ='Valuation output'!K7 | F25: ='Valuation output'!K8 | G25: =E25-F25
A26: 10 | B26: ='Valuation output'!L3 | C26: ='Valuation output'!L4 | D26: =B26*C26 | E26: ='Valuation output'!L7 | F26: ='Valuation output'!L8 | G26: =E26-F26
A27: Terminal year | B27: ='Valuation output'!M3 | C27: ='Valuation output'!M4 | D27: =B27*C27 | E27: ='Valuation output'!M7 | F27: ='Valuation output'!M8 | G27: =E27-F27
A28: The Value
A29: Terminal value | D29: ='Valuation output'!B18 | H29: This is the output from your valuation. It reflects your cash flows being discounted back at the cost of capital to get to your operating asset value, which then gets adjusted for the likelihood that your firm will not make it. We add cash and non-operating assets, subtract out debt and minority interests to get to value of equity.
A30: PV(Terminal value) | D30: ='Valuation output'!B19
A31: PV (CF over next 10 years) | D31: ='Valuation output'!B20
A32: Value of operating assets = | D32: ='Valuation output'!B21
A33: Adjustment for distress | D33: =D32-'Valuation output'!B24 | E33: Probability of failure = | G33: ='Valuation output'!B22
A34: - Debt & Minority Interests | D34: ='Valuation output'!B25+'Valuation output'!B26
A35: + Cash & Other Non-operating assets | D35: ='Valuation output'!B27+'Valuation output'!B28
A36: Value of equity | D36: =D32-D33-D34+D35
A37: - Value of equity options | D37: ='Valuation output'!B30
A38: Number of shares | D38: ='Valuation output'!B32
A39: Value per share | D39: =(D36-D37)/D38 | E39: Stock was trading at = | G39: ='Input sheet'!B22

Sheet Valuation as picture
A1: You can modify this picture and bring in relevant details to back up your cost of capital and other details that you think flesh out your company's valuation story.
A3: ='Input sheet'!B4 | O3: ='Input sheet'!B3
A5: Base Year and Comparison | E5: Growth Story | H5: Profitability Story | K5: Growth Efficiency Story
B6: Company | C6: Industry | E6: ='Stories to Numbers'!G9 | H6: ='Stories to Numbers'!G10 | K6: ='Stories to Numbers'!G12 | O6: Terminal Value
A7: Revenue Growth | B7: ='Input sheet'!I25 | C7: ='Input sheet'!K25 | O7: Growth Rate | P7: =O16
A8: Revenue | B8: ='Valuation output'!B3 | O8: Cost of capital | P8: ='Valuation output'!M12
A9: Operating Margin | B9: ='Valuation output'!B4 | C9: ='Input sheet'!K26 | O9: Return on capital | P9: ='Valuation output'!M40
A10: Operating Income | B10: ='Valuation output'!B5 | O10: Reinvestment Rate | P10: =P7/P9
A11: EBIT (1-t) | B11: ='Valuation output'!B7
A15: ='Valuation output'!A19 | B15: ='Valuation output'!B19 | E15: ='Valuation output'!C1 | F15: ='Valuation output'!D1 | G15: ='Valuation output'!E1 | H15: ='Valuation output'!F1 | I15: ='Valuation output'!G1 | J15: ='Valuation output'!H1 | K15: ='Valuation output'!I1 | L15: ='Valuation output'!J1 | ... O15: ='Valuation output'!M1
A16: ='Valuation output'!A20 | B16: ='Valuation output'!B20 | D16: Revenue Growth | E16: ='Valuation output'!C2 | F16: ='Valuation output'!D2 | G16: ='Valuation output'!E2 | H16: ='Valuation output'!F2 | I16: ='Valuation output'!G2 | J16: ='Valuation output'!H2 | K16: ='Valuation output'!I2 | L16: ='Valuation output'!J2 | ... O16: ='Valuation output'!M2
A17: ='Valuation output'!A22 | B17: ='Valuation output'!B22 | D17: Revenue | E17: ='Valuation output'!C3 | F17: ='Valuation output'!D3 | G17: ='Valuation output'!E3 | H17: ='Valuation output'!F3 | I17: ='Valuation output'!G3 | J17: ='Valuation output'!H3 | K17: ='Valuation output'!I3 | L17: ='Valuation output'!J3 | ... O17: ='Valuation output'!M3
A18: ='Valuation output'!A24 | B18: ='Valuation output'!B24 | D18: Operating Margin | E18: ='Valuation output'!C4 | F18: ='Valuation output'!D4 | G18: ='Valuation output'!E4 | H18: ='Valuation output'!F4 | I18: ='Valuation output'!G4 | J18: ='Valuation output'!H4 | K18: ='Valuation output'!I4 | L18: ='Valuation output'!J4 | ... O18: ='Valuation output'!M4
A19: ='Valuation output'!A25 | B19: ='Valuation output'!B25 | D19: Operating Income | E19: ='Valuation output'!C5 | F19: ='Valuation output'!D5 | G19: ='Valuation output'!E5 | H19: ='Valuation output'!F5 | I19: ='Valuation output'!G5 | J19: ='Valuation output'!H5 | K19: ='Valuation output'!I5 | L19: ='Valuation output'!J5 | ... O19: ='Valuation output'!M5
A20: ='Valuation output'!A26 | B20: ='Valuation output'!B26 | D20: EBIT (1-t) | E20: ='Valuation output'!C7 | F20: ='Valuation output'!D7 | G20: ='Valuation output'!E7 | H20: ='Valuation output'!F7 | I20: ='Valuation output'!G7 | J20: ='Valuation output'!H7 | K20: ='Valuation output'!I7 | L20: ='Valuation output'!J7 | ... O20: ='Valuation output'!M7
A21: ='Valuation output'!A27 | B21: ='Valuation output'!B27 | D21: Reinvestment | E21: ='Valuation output'!C8 | F21: ='Valuation output'!D8 | G21: ='Valuation output'!E8 | H21: ='Valuation output'!F8 | I21: ='Valuation output'!G8 | J21: ='Valuation output'!H8 | K21: ='Valuation output'!I8 | L21: ='Valuation output'!J8 | ... O21: ='Valuation output'!M8
A22: ='Valuation output'!A28 | B22: ='Valuation output'!B28 | D22: FCFF | E22: ='Valuation output'!C9 | F22: ='Valuation output'!D9 | G22: ='Valuation output'!E9 | H22: ='Valuation output'!F9 | I22: ='Valuation output'!G9 | J22: ='Valuation output'!H9 | K22: ='Valuation output'!I9 | L22: ='Valuation output'!J9 | ... O22: ='Valuation output'!M9
A23: ='Valuation output'!A29 | B23: ='Valuation output'!B29 | N23: ='Valuation output'!B18
A24: ='Valuation output'!A30 | B24: ='Valuation output'!B30
A25: ='Valuation output'!A31 | B25: ='Valuation output'!B31 | D25: Cost of Capital | E25: ='Valuation output'!C12 | F25: ='Valuation output'!D12 | G25: ='Valuation output'!E12 | H25: ='Valuation output'!F12 | I25: ='Valuation output'!G12 | J25: ='Valuation output'!H12 | K25: ='Valuation output'!I12 | L25: ='Valuation output'!J12 | ... N25: ='Valuation output'!L12
A26: ='Valuation output'!A32 | B26: ='Valuation output'!B32 | D26: Cumulated WACC | E26: ='Valuation output'!C13 | F26: ='Valuation output'!D13 | G26: ='Valuation output'!E13 | H26: ='Valuation output'!F13 | I26: ='Valuation output'!G13 | J26: ='Valuation output'!H13 | K26: ='Valuation output'!I13 | L26: ='Valuation output'!J13 | ... N26: ='Valuation output'!L13
A27: ='Valuation output'!A33 | B27: ='Valuation output'!B33
D28: Sales to Capital | E28: ='Valuation output'!C38 | F28: ='Valuation output'!D38 | G28: ='Valuation output'!E38 | H28: ='Valuation output'!F38 | I28: ='Valuation output'!G38 | J28: ='Valuation output'!H38 | K28: ='Valuation output'!I38 | L28: ='Valuation output'!J38 | ... N28: ='Valuation output'!L38
A29: Price per share | B29: ='Stories to Numbers'!G39 | D29: ROIC | E29: ='Valuation output'!C40 | F29: ='Valuation output'!D40 | G29: ='Valuation output'!E40 | H29: ='Valuation output'!F40 | I29: ='Valuation output'!G40 | J29: ='Valuation output'!H40 | K29: ='Valuation output'!I40 | L29: ='Valuation output'!J40 | ... O29: ='Valuation output'!M40
A30: % Under or Over Valued | B30: =B29/B27-1
D32: Risk Story | G32: Competitive Advantages
D33: ='Stories to Numbers'!G14 | G33: ='Stories to Numbers'!G13

Sheet Diagnostics
A1: Step 1: Check revenue growth rate | D1: Your forecasts | G1: Questions to ask
B2: Industry Average | C2: Most Recent year | D2: Next year | E2: Years 2-5 | G2: 1. If you are forecasting a revenue growth rate > industry average, is your company small?
A3: Annual Revenue Growth Rate | B3: ='Input sheet'!J25 | C3: ='Input sheet'!I25 | D3: ='Valuation output'!C2 | E3: ='Valuation output'!D2 | G3: 2. If your forecasted revenue growth rate is very different from your company's most recent year of growth, what is the reason?
A5: Step 2: Check dollar revenues
B6: Most Recent year | C6: Next year | D6: Year 5 | E6: Year 10 | G6: 1. How big is the total market today?
A7: Revenues | B7: ='Valuation output'!B3 | C7: ='Valuation output'!C3 | D7: ='Valuation output'!G3 | E7: ='Valuation output'!L3 | G7: 2. How much revenues do the biggest companies in that market make today?
G8: 3. How much growth is there in the total market?
G9: 4. What type of market share are you forecasting for your company in year 10?
A11: Step 3: Check your margins | B11: Most Recent year | C11: Next year | D11: Year 5 | E11: Year 10 | G11: 1. What are the margins of the industry that the company is in?
A12: Operating Margin | B12: ='Valuation output'!B4 | C12: ='Valuation output'!C4 | D12: ='Valuation output'!G4 | E12: ='Valuation output'!M4 | G12: 2. What are the unit economics of the business? (How much does it cost you to make the extra unit that you sell?
G13: 3. What does the competition in this business look like?
A15: Step 4: Check how much you are reinvesting
B16: Most Recent year | C16: Next year | D16: Year 5 | E16: Year 10 | G16: 1. is the growth that you are forecasting bounce-back growth or new growth?
A17: Sales to Capital | B17: ='Input sheet'!I27 | C17: ='Valuation output'!C38 | D17: ='Valuation output'!G38 | E17: ='Valuation output'!L38 | G17: 2. How much excess capacity do you have to service near term growth?
G18: 3. Does investment efficiency in this business change as companies get bigger?
A19: Reinvestment effect on cash flows
B20: $ Value | C20: As % of value
A21: PV of after-tax operating income for next 10 yearas | B21: ='Valuation output'!C7*'Valuation output'!C13+'Valuation output'!D7*'Valuation output'!D13+'Valuation output'!E7*'Valuation output'!E13+'Valuation output'!F7*'Valuation output'!F13+'Valuation output'!G7*'Valuation output'!G13+'Valuation output'!H7*'Valuation output'!H13+'Valuation output'!I7*'Valuation output'!I13+'Valuation output'!J7*'Valuation output'!J13+'Valuation output'!K7*'Valuation output'!K13+'Valuation output'!L7*'Valuation output'!L13 | C21: =B21/B21 | G21: 1. Is your reinvestment consitent with your revenue growth forecast?
A22: Value effect of reinvestment for next 10 years | B22: =B21-B23 | C22: =B22/B21 | G22: 2. Are you comfortable with your return on capital in year 10?
A23: PV of FCFF for next ten years | B23: ='Valuation output'!B20 | C23: =C21-C22
A25: Return on capital effects
B26: Most recent year | C26: Marginal (1-10) | D26: ROC in year 10 | E26: Stable ROC
A27: Return on capital | B27: ='Valuation output'!B40 | C27: =('Valuation output'!L7-'Valuation output'!B7)/('Valuation output'!L39-'Valuation output'!B39) | D27: ='Valuation output'!L40 | E27: ='Valuation output'!M40
A29: Step 5: Risk Metrics
B30: Industry Average | C30: Compounded | D30: Year 1-5 | E30: Stable Growth | G30: 1. How does your cost of capital compare to the industry average?
A31: Cost of capital | B31: ='Input sheet'!J31 | C31: =(1/'Valuation output'!L13)^(1/10)-1 | D31: ='Valuation output'!C12 | E31: ='Valuation output'!M12 | G31: 2. What is happenign to your cost of capital over time? Why?
G32: 3. Is your failure rate consistent with your company's characteristics?
A33: Failure Rate | B33: ='Valuation output'!B22
A35: Step 6: Price versus Value
A36: Your calculated value as a percent of current price | B36: ='Valuation output'!B33/'Valuation output'!B34
B37: =IF(B36="NA","Value is negative. See below",IF(B36>2,"Value seems high. See below",IF(B36<0.5,"Value seems low. See below"," ")))
A38: Inputs | B38: If calculated value is negative or looks too low | C38: If calculated value looks too high
A39: Revenue growth rate (input cell B25, B27) | B39: Increase revenue growth rate | C39: Decrease revenue growth rate
A40: Operating margin (B26, B28) | B40: Increase the target pre-tax operating margin | C40: Decrease the target pre-tax operating margin
A41: Sales to Capital (B30-B32) | B41: Increase the sales/capital ratio | C41: Decrease the sales/capital ratio
A42: Return on capital in perpetuity (B48, B49) | B42: Increase relative to your cost of capital | C42: If higher than your cost of capital, lower towards your cost of capital | D42: T

Sheet Option value
A1: Note: This worksheet is the most finicky of all of the worksheets in this spreadsheet. If you start to get errors, here is a quick fix. Go into cell B12 and replace the contents with a number (say 5), and then undo your action. The spreadsheet will fix itself magically.
A3: Valuing Options or Warrants
A4: Enter the current stock price = | B4: ='Input sheet'!B22
A5: Enter the strike price on the option = | B5: ='Input sheet'!B39
A6: Enter the expiration of the option = | B6: ='Input sheet'!B40
A7: Enter the standard deviation in stock prices = | B7: ='Input sheet'!B41 | C7: (volatility)
A8: Enter the annualized dividend yield on stock = | B8: 0
A9: Enter the treasury bond rate = | B9: ='Input sheet'!B34
A10: Enter the number of warrants (options) outstanding = | B10: ='Input sheet'!B38
A11: Enter the number of shares outstanding = | B11: ='Input sheet'!B21
A13: Do not input any numbers below this line
A14: Dilution-adjusted Black-Scholes
A15: Stock Price= | B15: =B4 | C15: # Warrants issued= | D15: =B10
A16: Strike Price= | B16: =B5 | C16: # Shares outstanding= | D16: =B11
A17: Adjusted S = | B17: =(B15*D16+B28*D15)/(D16+D15) | C17: T.Bond rate= | D17: =B9
A18: Adjusted K = | B18: =B16 | C18: Variance= | D18: =B7^2
A19: Expiration (in years) = | B19: =B6 | C19: Annualized dividend yield= | D19: =B8
C20: Div. Adj. interest rate= | D20: =D17-D19
A22: d1 = | B22: =(LN(B17/B18)+(D20+(D18/2))*B19)/(((D18)^(0.5))*(B19^0.5))
A23: N (d1) = | B23: =NORMSDIST(B22)
A25: d2 = | B25: =B22-((D18^0.5)*(B19^(0.5)))
A26: N (d2) = | B26: =NORMSDIST(B25)
A28: Value per option = | B28: =((EXP((0-D19)*B19))*B17*B23-B18*(EXP((0-D17)*B19))*B26)
A29: Value of all options outstanding = | B29: =B28*B10

Sheet Synthetic rating
A1: If you have negative operating income, this spreadsheet will offer you a D rating. Do not use that rating as your cost of debt for a going concern. Insread give your company a low, but going concern rating like BB and use that cost of debt.
A4: Inputs for synthetic rating estimation
A5: Please read the special cases worksheet (see below) before you use this spreadsheet.
A6: Before you use this spreadsheet, make sure that the iteration box (under calculation options in excel) is checked.
A7: Enter the type of firm = | C7: ='Cost of capital worksheet'!B36
A8: Enter current Earnings before interest and taxes (EBIT) = | F8: =IF('Input sheet'!B17="Yes",'Input sheet'!B12+'Operating lease converter'!F32,'Input sheet'!B12) | G8: (Add back only long term interest expense for financial firms)
A9: Enter current interest expenses = | F9: =IF('Input sheet'!B17="Yes",'Cost of capital worksheet'!B31+'Operating lease converter'!C28*'Operating lease converter'!C15,'Cost of capital worksheet'!B31) | G9: (Use only long term interest expense for financial firms)
A10: Enter long term risk free rate = | F10: ='Input sheet'!B34
A11: Output
A12: Interest coverage ratio = | D12: =IF(F9=0,1000000,IF(F8<0,-100000,F8/F9))
A13: Estimated Bond Rating = | D13: =IF(C7=1,VLOOKUP(D12,A22:D36,3),(IF(C7=2,VLOOKUP(D12,A41:D55,3),VLOOKUP(D12,F22:I36,3)))) | F13: Note: If you get REF! All over the place, set the operating lease commitment question in cell F5
A14: Estimated Company Default Spread = | D14: =IF(C7=1,VLOOKUP(D12,A22:D36,4),(IF(C7=2,VLOOKUP(D12,A41:D55,4),VLOOKUP(D12,F22:I36,4)))) | F14: to No, and then reset it to Yes. It should work.
A15: Estimated County Default Spread (if any) = | D15: =VLOOKUP('Input sheet'!B7,'Country equity risk premiums'!A5:C196,3)
A16: Estimated Cost of Debt = | D16: =F10+D14+D15
A18: If you want to update the spreads listed below, please visit http://www.bondsonline.com
A19: For large manufacturing firms | J19: Default Probabilities over time (1 - 10 year time horizons)
A20: If interest coverage ratio is | J20: Rating | K20: 1 | L20: 2 | M20: 3 | N20: 4 | O20: 5 | P20: 6 | Q20: 7 | R20: 8 | S20: 9 | T20: 10
A21: > | B21: ≤ to | C21: Rating is | D21: Spread is | J21: AAA | K21: 0 | L21: 0.0003 | M21: 0.0013 | N21: 0.0024 | O21: 0.0035 | P21: 0.0045 | Q21: 0.0051 | R21: 0.0059 | S21: 0.0064 | T21: 0.007
A22: -100000 | B22: 0.199999 | C22: D2/D | D22: 0.19 | J22: AA | K22: 0.0002 | L22: 0.0006 | M22: 0.0012 | N22: 0.0021 | O22: 0.0031 | P22: 0.0042 | Q22: 0.005 | R22: 0.0058 | S22: 0.0065 | T22: 0.0072
A23: 0.2 | B23: 0.649999 | C23: C2/C | D23: 0.16 | J23: A | K23: 0.0005 | L23: 0.0014 | M23: 0.0023 | N23: 0.0035 | O23: 0.0047 | P23: 0.0062 | Q23: 0.0079 | R23: 0.0093 | S23: 0.0108 | T23: 0.0124
A24: 0.65 | B24: 0.799999 | C24: Ca2/CC | D24: 0.126101 | J24: BBB | K24: 0.0016 | L24: 0.0045 | M24: 0.0078 | N24: 0.0117 | O24: 0.0158 | P24: 0.0198 | Q24: 0.0233 | R24: 0.0267 | S24: 0.03 | T24: 0.0332
A25: 0.8 | B25: 1.249999 | C25: Caa/CCC | D25: 0.0885 | J25: BB | K25: 0.0061 | L25: 0.0192 | M25: 0.0348 | N25: 0.0505 | O25: 0.0652 | P25: 0.0785 | Q25: 0.0901 | R25: 0.1004 | S25: 0.1097 | T25: 0.1178
A26: 1.25 | B26: 1.499999 | C26: B3/B- | D26: 0.050899 | J26: B | K26: 0.0333 | L26: 0.0771 | M26: 0.1155 | N26: 0.1458 | O26: 0.1693 | P26: 0.1883 | Q26: 0.2036 | R26: 0.216 | S26: 0.227 | T26: 0.2374
A27: 1.5 | B27: 1.749999 | C27: B2/B | D27: 0.032098 | J27: CCC/C | K27: 0.2708 | L27: 0.3664 | M27: 0.4141 | N27: 0.441 | O27: 0.4619 | P27: 0.4709 | Q27: 0.4826 | R27: 0.4905 | S27: 0.4976 | T27: 0.5038
A28: 1.75 | B28: 1.999999 | C28: B1/B+ | D28: 0.027531
A29: 2 | B29: 2.2499999 | C29: Ba2/BB | D29: 0.018395
A30: 2.25 | B30: 2.49999 | C30: Ba1/BB+ | D30: 0.013828
A31: 2.5 | B31: 2.999999 | C31: Baa2/BBB | D31: 0.011113
A32: 3 | B32: 4.249999 | C32: A3/A- | D32: 0.008872
A33: 4.25 | B33: 5.499999 | C33: A2/A | D33: 0.007751
A34: 5.5 | B34: 6.499999 | C34: A1/A+ | D34: 0.007003
A35: 6.5 | B35: 8.499999 | C35: Aa2/AA | D35: 0.005506
A36: 8.5 | B36: 100000 | C36: Aaa/AAA | D36: 0.004
A38: For smaller and riskier firms
A39: If interest coverage ratio is
A40: greater than | B40: ≤ to | C40: Rating is | D40: Spread is
A41: -100000 | B41: 0.499999 | C41: D2/D | D41: 0.19 | G41: Rating is | H41: Spread is
A42: 0.5 | B42: 0.799999 | C42: C2/C | D42: 0.16 | G42: A1/A+ | H42: 0.007003
A43: 0.8 | B43: 1.249999 | C43: Ca2/CC | D43: 0.126101 | G43: A2/A | H43: 0.007751
A44: 1.25 | B44: 1.499999 | C44: Caa/CCC | D44: 0.0885 | G44: A3/A- | H44: 0.008872
...

Sheet R& D converter
A1: R & D Converter
A2: This spreadsheet converts R&D expenses from operating to capital expenses. It makes the appropriate adjustments to operating income, net
A3: income, the book value of assets and the book value of equity.
A5: Inputs
A6: Over how many years do you want to amortize R&D expenses | F6: 3 | G6: ! If in doubt, use the lookup table below
A7: Enter the current year's R&D expense = | F7: 85622 | G7: The maximum allowed is ten years
A8: Enter R& D expenses for past years: the number of years that you will need to enter will be determined by the amortization period
A9: Do not input numbers in the first column (Year). It will get automatically updated based on the input above.
A10: Year | B10: R& D Expenses
A11: -1 | B11: 73213 | C11: ! Year -1 is the year prior to the most recent 12 months
A12: =IF((0-A11)<$F$6,IF(A11>-1,,A11-1),) | B12: 56052 | C12: ! Year -2 is the two years prior to the most recent 12 months
A13: =IF((0-A12)<$F$6,IF(A12>-1,,A12-1),) | B13: 42740
A14: =IF((0-A13)<$F$6,IF(A13>-1,,A13-1),)
A15: =IF((0-A14)<$F$6,IF(A14>-1,,A14-1),)
A16: =IF((0-A15)<$F$6,IF(A15>-1,,A15-1),)
A17: =IF((0-A16)<$F$6,IF(A16>-1,,A16-1),)
A18: =IF((0-A17)<$F$6,IF(A17>-1,,A17-1),)
A19: =IF((0-A18)<$F$6,IF(A18>-1,,A18-1),)
A20: =IF((0-A19)<$F$6,IF(A19>-1,,A19-1),)
A22: Output
A23: Year | B23: R&D Expense | C23: Unamortized portion | E23: Amortization this year
A24: Current | B24: =F7 | C24: =1 | D24: =B24*C24
A25: =A11 | B25: =B11 | C25: =IF(A25<0,($F$6+A25)/$F$6,0) | D25: =B25*C25 | E25: =IF(A25<0,B25/$F$6,0)
A26: =A12 | B26: =B12 | C26: =IF(A26<0,($F$6+A26)/$F$6,0) | D26: =B26*C26 | E26: =IF(A26<0,B26/$F$6,0)
A27: =A13 | B27: =B13 | C27: =IF(A27<0,($F$6+A27)/$F$6,0) | D27: =B27*C27 | E27: =IF(A27<0,B27/$F$6,0)
A28: =A14 | B28: =B14 | C28: =IF(A28<0,($F$6+A28)/$F$6,0) | D28: =B28*C28 | E28: =IF(A28<0,B28/$F$6,0)
A29: =A15 | B29: =B15 | C29: =IF(A29<0,($F$6+A29)/$F$6,0) | D29: =B29*C29 | E29: =IF(A29<0,B29/$F$6,0)
A30: =A16 | B30: =B16 | C30: =IF(A30<0,($F$6+A30)/$F$6,0) | D30: =B30*C30 | E30: =IF(A30<0,B30/$F$6,0)
A31: =A17 | B31: =B17 | C31: =IF(A31<0,($F$6+A31)/$F$6,0) | D31: =B31*C31 | E31: =IF(A31<0,B31/$F$6,0)
A32: =A18 | B32: =B18 | C32: =IF(A32<0,($F$6+A32)/$F$6,0) | D32: =B32*C32 | E32: =IF(A32<0,B32/$F$6,0)
A33: =A19 | B33: =B19 | C33: =IF(A33<0,($F$6+A33)/$F$6,0) | D33: =B33*C33 | E33: =IF(A33<0,B33/$F$6,0)
A34: =A20 | B34: =B20 | C34: =IF(A34<0,($F$6+A34)/$F$6,0) | D34: =B34*C34 | E34: =IF(A34<0,B34/$F$6,0)
A35: Value of Research Asset = | D35: =SUM(D24:D34) | E35: =SUM(E25:E34)
A37: Amortization of asset for current year = | D37: =E35
A39: Adjustment to Operating Income = | D39: =F7-D37 | E39: ! A positive number indicates an increase in operating income (add to reported EBIT)
A40: Tax Effect of R&D Expensing | D40: =D39*'Input sheet'!B24
A42: Lookup Table for Amortizable Lives
A43: Industry Name | B43: Amortization Period
A44: Advertising | B44: 2
A45: Aerospace/Defense | B45: 10
...

Sheet Operating lease converter
A1: Operating Lease Converter
A2: The yellow cells are input cells. Please enter them.
A3: Inputs | H3: Until 2019, this worksheet had to be used for every firm with operating lease commitments, since accountants treated operating lease expenses as operating expenses. In 2019, IFRS and GAAP made the long-overdue change to treat leases as debt, and for firms that follow these standards, the conversion that I am doing on this spreadsheet is being done by accountants, with lease debt and operating income already adjusted. If that is the case, and you showed the lease debt as part of debt in the input page, please do not use this spreadsheet, since you will be double counting.
A4: Operating lease expense in current year = | E4: 295
A5: Operating Lease Commitments (From footnote to financials)
A6: Year | B6: Commitment | C6: ! Year 1 is next year, ….
A7: 1 | B7: 287
A8: 2 | B8: 235
A9: 3 | B9: 194
A10: 4 | B10: 151
A11: 5 | B11: 98
A12: 6 and beyond | B12: 605
A14: Output
A15: Pre-tax Cost of Debt = | C15: ='Cost of capital worksheet'!B37 | D15: ! If you do not have a cost of debt, use the synthetic rating estimator
A18: Number of years embedded in yr 6 estimate = | D18: =IF(B12>0,ROUND(B12/AVERAGE(B7:B11),0),0) | E18: ! I use the average lease expense over the first five years
E19: to estimate the number of years of expenses in yr 6
A20: Converting Operating Leases into debt
A21: Year | B21: Commitment | C21: Present Value
A22: =A7 | B22: =B7 | C22: =B22/(1+$C$15)^A22
A23: =A8 | B23: =B8 | C23: =B23/(1+$C$15)^A23
A24: =A9 | B24: =B9 | C24: =B24/(1+$C$15)^A24
A25: =A10 | B25: =B10 | C25: =B25/(1+$C$15)^A25
A26: =A11 | B26: =B11 | C26: =B26/(1+$C$15)^A26
A27: =A12 | B27: =IF(B12>0,IF(D18>0,B12/D18,B12),0) | C27: =IF(D18>0,(B27*(1-(1+C15)^(-D18))/C15)/(1+$C$15)^5,B27/(1+C15)^6) | D27: ! Commitment beyond year 6 converted into an annuity for ten years
A28: Debt Value of leases = | C28: =SUM(C22:C27)
A30: Restated Financials
A31: Depreciation on Operating Lease Asset = | F31: =C28/(5+D18) | G31: ! I use straight line depreciation
A32: Adjustment to Operating Earnings = | F32: =E4-F31 | G32: ! Add this amount to pre-tax operating income
A33: Adjustment to Total Debt outstanding = | F33: =C28 | G33: ! Add this amount to debt
A34: Adjustment to Depreciation = | F34: =C28/(5+D18)

Sheet Cost of capital worksheet
A1: You can use this spreadsheet to compute your cost of capital. You can either use the built-in data to compute key inputs (beta, equity risk premium, default spread) or enter them directly. If you choose to use the built in ERP data, you can update the ERP numbers to reflect a more current mature market premuum (since the spreadsheet uses the start of the year numbers).
A3: Estimation of Current Cost of Capital | G3: Operating Countries ERP calculator
A4: There are four ways in whch you can estimate your cost of capital. In the first, you can directly input a cost of captial. In the second, you can work through your company's cost of capital inputs in detail, entering business, geogaphical mix and debt, and I will help you estimate a cost of capital. In the third, you can look up the cost of capital for the industry or industries your firm belongs to and in the fourth, you can use a crosssectional distribution of costs of capital for companies at the start of the year to make your estimate. | G4: Country | H4: Revenues | I4: ERP | J4: Weight | K4: Weighted ERP
G5: United States | H5: 193636 | I5: =IF(H5=0,0,VLOOKUP(G5,'Country equity risk premiums'!$A$5:$D$196,4)) | J5: =IF(H5>0,H5/$H$18,) | K5: =IF(J5=0,0,I5*J5) | M5: The last two rows in each of country/region risk premium tables is set aside for your input to provide you with flexibility to enter some numbers directly. For instance, assume that you have a company that breaks its revenues down into three countries and then puts the rest into "Rest of the World". You can enter the "Rest of the World" in one of these two rows and enter an equity risk premium for the rest of the world. The easiest way to do that is to go into the country equity risk premium worksheet and change the GDP for the three countries that you have data for to zero and compute the global weighted average ERP for the remaining countries. With the regional worksheet, you can use the last two rows to enter the data for an individual country (usually the domestic country) that might be broken out though the rest of the revenues are broken down by region. You can look up the ERP for the country in the country ERP worksheet.
G6: China | H6: 500 | I6: =IF(H6=0,0,VLOOKUP(G6,'Country equity risk premiums'!$A$5:$D$196,4)) | J6: =IF(H6>0,H6/$H$18,) | K6: =IF(J6=0,0,I6*J6)
I7: =IF(H7=0,0,VLOOKUP(G7,'Country equity risk premiums'!$A$5:$D$196,4)) | J7: =IF(H7>0,H7/$H$18,) | K7: =IF(J7=0,0,I7*J7)
I8: =IF(H8=0,0,VLOOKUP(G8,'Country equity risk premiums'!$A$5:$D$196,4)) | J8: =IF(H8>0,H8/$H$18,) | K8: =IF(J8=0,0,I8*J8)
I9: =IF(H9=0,0,VLOOKUP(G9,'Country equity risk premiums'!$A$5:$D$196,4)) | J9: =IF(H9>0,H9/$H$18,) | K9: =IF(J9=0,0,I9*J9)
I10: =IF(H10=0,0,VLOOKUP(G10,'Country equity risk premiums'!$A$5:$D$196,4)) | J10: =IF(H10>0,H10/$H$18,) | K10: =IF(J10=0,0,I10*J10)
A11: Which approach will you be using? | B11: Detailed | I11: =IF(H11=0,0,VLOOKUP(G11,'Country equity risk premiums'!$A$5:$D$196,4)) | J11: =IF(H11>0,H11/$H$18,) | K11: =IF(J11=0,0,I11*J11)
A12: If direct input, enter cost of capital to use | B12: 0.09 | I12: =IF(H12=0,0,VLOOKUP(G12,'Country equity risk premiums'!$A$5:$D$196,4)) | J12: =IF(H12>0,H12/$H$18,) | K12: =IF(J12=0,0,I12*J12)
A13: Cost of capital based upon approach = | B13: =IF(B11="I will input",B12,IF(B11="Detailed",E62,IF(B11="Industry Average",B67,B72))) | I13: =IF(H13=0,0,VLOOKUP(G13,'Country equity risk premiums'!$A$5:$D$196,4)) | J13: =IF(H13>0,H13/$H$18,) | K13: =IF(J13=0,0,I13*J13)
I14: =IF(H14=0,0,VLOOKUP(G14,'Country equity risk premiums'!$A$5:$D$196,4)) | J14: =IF(H14>0,H14/$H$18,) | K14: =IF(J14=0,0,I14*J14)
A15: Approach 1: Detailed Cost of Capital | I15: =IF(H15=0,0,VLOOKUP(G15,'Country equity risk premiums'!$A$5:$D$196,4)) | J15: =IF(H15>0,H15/$H$18,) | K15: =IF(J15=0,0,I15*J15)
A16: Inputs | G16: Rest of the World | H16: 31335 | I16: 0.0641 | J16: =IF(H16>0,H16/$H$18,) | K16: =IF(J16=0,0,I16*J16)
A17: Equity | J17: =IF(H17>0,H17/$H$18,) | K17: =IF(J17=0,0,I17*J17)
A18: Number of Shares outstanding = | B18: ='Input sheet'!B21 | G18: Total | H18: =SUM(H5:H17) | J18: =SUM(J5:J17) | K18: =SUM(K5:K17)
A19: Current Market Price per share = | B19: ='Input sheet'!B22 | G19: Operating Regions ERP calculator
G20: Region | H20: Revenues | I20: ERP | J20: Weight | K20: Weighted ERP
A21: Approach for estimating beta | B21: Single Business(US) | G21: ='Country equity risk premiums'!A201 | I21: ='Country equity risk premiums'!B201 | J21: =H21/$H$32 | K21: =I21*J21
A22: If direct input, enter levered beta (or regression beta) | B22: 1.2 | G22: ='Country equity risk premiums'!A202 | H22: 5455 | I22: ='Country equity risk premiums'!B202 | J22: =H22/$H$32 | K22: =I22*J22
A23: Unlevered beta = | B23: =IF(B21="Single Business(US)",VLOOKUP('Input sheet'!B8,'Industry Averages(US)'!A2:G95,7),IF(B21="Multibusiness(US)",K48,IF(B21="Single Business(Global)",VLOOKUP('Input sheet'!B9,'Industry Averages (Global)'!A2:G95,7),'Cost of capital worksheet'!K64))) | G23: ='Country equity risk premiums'!A203 | I23: ='Country equity risk premiums'!B203 | J23: =H23/$H$32 | K23: =I23*J23
A24: Riskfree Rate = | B24: ='Input sheet'!B34 | G24: ='Country equity risk premiums'!A204 | I24: ='Country equity risk premiums'!B204 | J24: =H24/$H$32 | K24: =I24*J24
A25: What approach do you want to use to input ERP? | B25: Will Input | G25: ='Country equity risk premiums'!A205 | H25: 5830 | I25: ='Country equity risk premiums'!B205 | J25: =H25/$H$32 | K25: =I25*J25
A26: Direct input for ERP (if you choose "will input" | B26: 0.05 | G26: ='Country equity risk premiums'!A206 | I26: ='Country equity risk premiums'!B206 | J26: =H26/$H$32 | K26: =I26*J26
A27: Equity Risk Premium used in cost of equity = | B27: =IF(B25="Will Input",B26,IF(B25="Country of Incorporation",VLOOKUP('Input sheet'!B7,'Country equity risk premiums'!A5:E195,4),IF(B25="Operating regions",'Cost of capital worksheet'!K32,'Cost of capital worksheet'!K18))) | G27: ='Country equity risk premiums'!A207 | I27: ='Country equity risk premiums'!B207 | J27: =H27/$H$32 | K27: =I27*J27
G28: ='Country equity risk premiums'!A208 | H28: 16774 | I28: ='Country equity risk premiums'!B208 | J28: =H28/$H$32 | K28: =I28*J28
A29: Debt | G29: ='Country equity risk premiums'!A209 | I29: ='Country equity risk premiums'!B209 | J29: =H29/$H$32 | K29: =I29*J29
A30: Book Value of Straight Debt = | B30: ='Input sheet'!B15 | G30: EMEA | H30: 8078 | I30: 0.0587 | J30: =H30/$H$32 | K30: =I30*J30
A31: Interest Expense on Debt = | B31: ='Input sheet'!B13 | G31: Rest of the World | H31: 10924 | I31: 0.055 | J31: =H31/$H$32 | K31: =I31*J31
A32: Average Maturity = | B32: 3 | G32: Total | H32: =SUM(H21:H31) | J32: =SUM(J21:J31) | K32: =SUM(K21:K31)
A33: Approach for estimating pre-tax cost of debt | B33: Actual rating
A34: If direct input, input the pre-tax cost of debt | B34: 0.04 | G34: Multi Business (US Industry Averages)
A35: If actual rating, input the rating | B35: Aaa/AAA | G35: Business | H35: Revenues | I35: EV/Sales | J35: Estimated Value | K35: Unlevered Beta | L35: Cost of capital
A36: If synethetic rating, input the type of company | B36: 2 | G36: Computers/Peripherals | H36: 195010 | I36: =IF(G36=0,,VLOOKUP(G36,'Industry Averages(US)'!$A$2:$S$95,15)) | J36: =H36*I36 | K36: =IF(I36=0,0,VLOOKUP(G36,'Industry Averages(US)'!$A$2:$S$95,7)) | L36: =IF(I36=0,0,VLOOKUP(G36,'Industry Averages(US)'!$A$2:$S$95,13))
A37: Pre-tax Cost of Debt = | B37: =IF(B33="Direct Input",B34,IF(B33="Synthetic Rating",'Synthetic rating'!D16,B24+VLOOKUP('Cost of capital worksheet'!B35,'Synthetic rating'!G42:H56,2))) | G37: Electronics (General) | H37: 43000 | I37: =IF(G37=0,,VLOOKUP(G37,'Industry Averages(US)'!$A$2:$S$95,15)) | J37: =H37*I37 | K37: =IF(I37=0,0,VLOOKUP(G37,'Industry Averages(US)'!$A$2:$S$95,7)) | L37: =IF(I37=0,0,VLOOKUP(G37,'Industry Averages(US)'!$A$2:$S$95,13))
A38: Tax Rate = | B38: ='Input sheet'!B24 | G38: Entertainment | H38: 15000 | I38: =IF(G38=0,,VLOOKUP(G38,'Industry Averages(US)'!$A$2:$S$95,15)) | J38: =H38*I38 | K38: =IF(I38=0,0,VLOOKUP(G38,'Industry Averages(US)'!$A$2:$S$95,7)) | L38: =IF(I38=0,0,VLOOKUP(G38,'Industry Averages(US)'!$A$2:$S$95,13))
I39: =IF(G39=0,,VLOOKUP(G39,'Industry Averages(US)'!$A$2:$S$95,15)) | J39: =H39*I39 | K39: =IF(I39=0,0,VLOOKUP(G39,'Industry Averages(US)'!$A$2:$S$95,7)) | L39: =IF(I39=0,0,VLOOKUP(G39,'Industry Averages(US)'!$A$2:$S$95,13))
A40: Book Value of Convertible Debt = | B40: 0 | I40: =IF(G40=0,,VLOOKUP(G40,'Industry Averages(US)'!$A$2:$S$95,15)) | J40: =H40*I40 | K40: =IF(I40=0,0,VLOOKUP(G40,'Industry Averages(US)'!$A$2:$S$95,7)) | L40: =IF(I40=0,0,VLOOKUP(G40,'Industry Averages(US)'!$A$2:$S$95,13))
A41: Interest Expense on Convertible = | B41: 0 | I41: =IF(G41=0,,VLOOKUP(G41,'Industry Averages(US)'!$A$2:$S$95,15)) | J41: =H41*I41 | K41: =IF(I41=0,0,VLOOKUP(G41,'Industry Averages(US)'!$A$2:$S$95,7)) | L41: =IF(I41=0,0,VLOOKUP(G41,'Industry Averages(US)'!$A$2:$S$95,13))
...

Sheet Failure Rate worksheet
A1: Estimating the likelihood of failure
A2: Approach 1: Using a corporate bond rating
A4: Default Probabilities over time (1 - 10 year time horizons)
A5: Rating | B5: 1 | C5: 2 | D5: 3 | E5: 4 | F5: 5 | G5: 6 | H5: 7 | I5: 8 | J5: 9 | K5: 10
A6: AAA | B6: 0 | C6: 0.0003 | D6: 0.0013 | E6: 0.0024 | F6: 0.0035 | G6: 0.0045 | H6: 0.0051 | I6: 0.0059 | J6: 0.0064 | K6: 0.007
A7: AA | B7: 0.0002 | C7: 0.0006 | D7: 0.0012 | E7: 0.0021 | F7: 0.0031 | G7: 0.0042 | H7: 0.005 | I7: 0.0058 | J7: 0.0065 | K7: 0.0072
A8: A | B8: 0.0005 | C8: 0.0014 | D8: 0.0023 | E8: 0.0035 | F8: 0.0047 | G8: 0.0062 | H8: 0.0079 | I8: 0.0093 | J8: 0.0108 | K8: 0.0124
A9: BBB | B9: 0.0016 | C9: 0.0045 | D9: 0.0078 | E9: 0.0117 | F9: 0.0158 | G9: 0.0198 | H9: 0.0233 | I9: 0.0267 | J9: 0.03 | K9: 0.0332
A10: BB | B10: 0.0061 | C10: 0.0192 | D10: 0.0348 | E10: 0.0505 | F10: 0.0652 | G10: 0.0785 | H10: 0.0901 | I10: 0.1004 | J10: 0.1097 | K10: 0.1178
A11: B | B11: 0.0333 | C11: 0.0771 | D11: 0.1155 | E11: 0.1458 | F11: 0.1693 | G11: 0.1883 | H11: 0.2036 | I11: 0.216 | J11: 0.227 | K11: 0.2374
A12: CCC/C | B12: 0.2708 | C12: 0.3664 | D12: 0.4141 | E12: 0.441 | F12: 0.4619 | G12: 0.4709 | H12: 0.4826 | I12: 0.4905 | J12: 0.4976 | K12: 0.5038
A14: Thus, if you use the 10-year likelihood of failure, the chance of failure for a BB rated firm is 11.78%.
A16: Approach 2: Using corporate age (for young companies)
O17: Survial Rate Data from Bureau of Labor Statistics (2022)
C18: Agriculture | D18: Mining | E18: Utilities | F18: Construction | G18: Manufacturing | H18: Retail | I18: Transportation | J18: Information | K18: Health Care | L18: All Sectors | O18: Agriculture | P18: Mining | Q18: Utilities | R18: Construction | S18: Manufacturing | T18: Retail | U18: Transportation | V18: Information | W18: Health Care | X18: All Sectors
A19: Failure Rate given age | B19: 0 | C19: =1-O28 | D19: =1-P28 | E19: =1-Q28 | F19: =1-R28 | G19: =1-S28 | H19: =1-T28 | I19: =1-U28 | J19: =1-V28 | ... L19: =1-X28 | N19: 1 | O19: 0.823 | P19: 0.818 | Q19: 0.84 | R19: 0.743 | S19: 0.828 | T19: 0.831 | U19: 0.769 | V19: 0.752 | W19: 0.814 | X19: 0.783
B20: 1 | C20: =O19-O$28 | D20: =P19-P$28 | E20: =Q19-Q$28 | F20: =R19-R$28 | G20: =S19-S$28 | H20: =T19-T$28 | I20: =U19-U$28 | J20: =V19-V$28 | ... L20: =X19-X$28 | N20: 2 | O20: 0.748 | P20: 0.712 | Q20: 0.735 | R20: 0.598 | S20: 0.724 | T20: 0.724 | U20: 0.636 | V20: 0.627 | W20: 0.722 | X20: 0.662
B21: 2 | C21: =O20-O$28 | D21: =P20-P$28 | E21: =Q20-Q$28 | F21: =R20-R$28 | G21: =S20-S$28 | H21: =T20-T$28 | I21: =U20-U$28 | J21: =V20-V$28 | ... L21: =X20-X$28 | N21: 3 | O21: 0.661 | P21: 0.629 | Q21: 0.67 | R21: 0.456 | S21: 0.622 | T21: 0.631 | U21: 0.523 | V21: 0.533 | W21: 0.674 | X21: 0.566
B22: 3 | C22: =O21-O$28 | D22: =P21-P$28 | E22: =Q21-Q$28 | F22: =R21-R$28 | G22: =S21-S$28 | H22: =T21-T$28 | I22: =U21-U$28 | J22: =V21-V$28 | ... L22: =X21-X$28 | N22: 4 | O22: 0.612 | P22: 0.538 | Q22: 0.629 | R22: 0.371 | S22: 0.541 | T22: 0.565 | U22: 0.45 | V22: 0.464 | W22: 0.613 | X22: 0.498
B23: 4 | C23: =O22-O$28 | D23: =P22-P$28 | E23: =Q22-Q$28 | F23: =R22-R$28 | G23: =S22-S$28 | H23: =T22-T$28 | I23: =U22-U$28 | J23: =V22-V$28 | ... L23: =X22-X$28 | N23: 5 | O23: 0.574 | P23: 0.512 | Q23: 0.565 | R23: 0.332 | S23: 0.494 | T23: 0.521 | U23: 0.411 | V23: 0.419 | W23: 0.559 | X23: 0.454
B24: 5 | C24: =O23-O$28 | D24: =P23-P$28 | E24: =Q23-Q$28 | F24: =R23-R$28 | G24: =S23-S$28 | H24: =T23-T$28 | I24: =U23-U$28 | J24: =V23-V$28 | ... L24: =X23-X$28 | N24: 6 | O24: 0.541 | P24: 0.472 | Q24: 0.556 | R24: 0.306 | S24: 0.463 | T24: 0.485 | U24: 0.377 | V24: 0.372 | W24: 0.548 | X24: 0.423
B25: 6 | C25: =O24-O$28 | D25: =P24-P$28 | E25: =Q24-Q$28 | F25: =R24-R$28 | G25: =S24-S$28 | H25: =T24-T$28 | I25: =U24-U$28 | J25: =V24-V$28 | ... L25: =X24-X$28 | N25: 7 | O25: 0.516 | P25: 0.429 | Q25: 0.516 | R25: 0.284 | S25: 0.438 | T25: 0.457 | U25: 0.349 | V25: 0.34 | W25: 0.529 | X25: 0.396
B26: 7 | C26: =O25-O$28 | D26: =P25-P$28 | E26: =Q25-Q$28 | F26: =R25-R$28 | G26: =S25-S$28 | H26: =T25-T$28 | I26: =U25-U$28 | J26: =V25-V$28 | ... L26: =X25-X$28 | N26: 8 | O26: 0.495 | P26: 0.405 | Q26: 0.503 | R26: 0.271 | S26: 0.415 | T26: 0.433 | U26: 0.324 | V26: 0.314 | W26: 0.484 | X26: 0.371
B27: 8 | C27: =O26-O$28 | D27: =P26-P$28 | E27: =Q26-Q$28 | F27: =R26-R$28 | G27: =S26-S$28 | H27: =T26-T$28 | I27: =U26-U$28 | J27: =V26-V$28 | ... L27: =X26-X$28 | N27: 9 | O27: 0.465 | P27: 0.371 | Q27: 0.476 | R27: 0.258 | S27: 0.4 | T27: 0.41 | U27: 0.305 | V27: 0.274 | W27: 0.455 | X27: 0.348
B28: 9 | C28: =O27-O$28 | D28: =P27-P$28 | E28: =Q27-Q$28 | F28: =R27-R$28 | G28: =S27-S$28 | H28: =T27-T$28 | I28: =U27-U$28 | J28: =V27-V$28 | ... L28: =X27-X$28 | N28: 10 | O28: 0.449 | P28: 0.323 | Q28: 0.449 | R28: 0.247 | S28: 0.381 | T28: 0.39 | U28: 0.284 | V28: 0.255 | W28: 0.425 | X28: 0.328
B29: 10 | C29: =O28-O$28 | D29: =P28-P$28 | E29: =Q28-Q$28 | F29: =R28-R$28 | G29: =S28-S$28 | H29: =T28-T$28 | I29: =U28-U$28 | J29: =V28-V$28 | ... L29: =X28-X$28
A30: Source; Bureau of Labor Statistics
A31: Thus, if you are valuing a technology firm that is 6 years old, the chance of failure is 11.70%.
A33: Factors to consider
A34: 1. The likelihood of failure decreases for larger firms.
A35: 2. The likelihood of failure decreases with access to capital, and is thus lower for publicly traded firms or firms with multiple high profile VCs
A36: 3. The likelihood of failure decreases as revenue growth increases, since hope for future growth will sustain the firm.
A37: 4. The likelihood of failure decreases with better unit economics, higher gross margins on the additional units sold

Sheet Country equity risk premiums
A1: Mature Market ERP + | B1: 0.0423 | C1: Updated January 1, 2026
A2: Changing this number will update all your country equity risk premiums.
A4: Country | B4: Moody's rating | C4: Adj. Default Spread | D4: Equity Risk Premium | E4: Country Risk Premium | F4: Corporate Tax Rate
A5: Abu Dhabi | B5: Aa2 | C5: 0.0042 | D5: =$B$1+E5 | E5: 0.0064 | F5: 0.09
A6: Albania | B6: Ba3 | C6: 0.0306 | D6: =$B$1+E6 | E6: 0.0466 | F6: 0.15
A7: Algeria | B7: NR | C7: 0.0383 | D7: =$B$1+E7 | E7: 0.0583 | F7: 0.1007
A8: Andorra (Principality of) | B8: Baa1 | C8: 0.0136 | D8: =$B$1+E8 | E8: 0.0207 | F8: 0.1
A9: Angola | B9: B3 | C9: 0.0552 | D9: =$B$1+E9 | E9: 0.0841 | F9: 0.25
A10: Anguilla | B10: NR | C10: 0.04915183 | D10: =$B$1+E10 | E10: 0.074876823 | F10: 0.26526548
A11: Antigua & Barbuda | B11: NR | C11: 0.027785942 | D11: =$B$1+E11 | E11: 0.042328496 | F11: 0.31546691
A12: Argentina | B12: Caa1 | C12: 0.0637 | D12: =$B$1+E12 | E12: 0.0971 | F12: 0.35
A13: Armenia | B13: Ba3 | C13: 0.0306 | D13: =$B$1+E13 | E13: 0.0466 | F13: 0.18
A14: Aruba | B14: Baa3 | C14: 0.0187 | D14: =$B$1+E14 | E14: 0.0285 | F14: 0.22
A15: Australia | B15: Aaa | C15: 0 | D15: =$B$1+E15 | E15: 0 | F15: 0.3
A16: Austria | B16: Aa1 | C16: 0.0023 | D16: =$B$1+E16 | E16: 0.0036 | F16: 0.23
... A196: Zimbabwe | B196: NR | C196: 0.0765 | D196: =$B$1+E196 | E196: 0.1166 | F196: 0.159
A200: Region | B200: ERP | C200: Weighted Average: Default Spread | D200: Tax Rate | E200: Weighted Average: CRP | F200: Total GDP (in $ millions)
A201: Africa | B201: =$B$1+E201 | C201: 0.050672304 | D201: 0.27390174 | E201: 0.077193081 | F201: 2340875.2
A202: Asia | B202: =$B$1+E202 | C202: 0.0097961467 | D202: 0.25654535 | E202: 0.014923236 | F202: 34731689
A203: Australia & New Zealand | B203: =$B$1+E203 | C203: 2.6796848e-05 | D203: 0.29735221 | E203: 4.0821732e-05 | F203: 2018608.8
A204: Caribbean | B204: =$B$1+E204 | C204: 0.04915183 | D204: 0.26526548 | E204: 0.074876823 | F204: 347814.13
A205: Central and South America | B205: =$B$1+E205 | C205: 0.027785942 | D205: 0.31546691 | E205: 0.042328496 | F205: 6538486.9
A206: Eastern Europe | B206: =$B$1+E206 | C206: 0.021975562 | D206: 0.1763748 | E206: 0.033477091 | F206: 3491477.2
A207: Middle East | B207: =$B$1+E207 | C207: 0.013172609 | D207: 0.16120226 | E207: 0.020066864 | F207: 3565018.3
A208: North America | B208: =$B$1+E208 | C208: 0.0021647488 | D208: 0.25082522 | E208: 0.0021647488 | F208: 30994593
A209: Western Europe | B209: =$B$1+E209 | C209: 0.0068042645 | D209: 0.25557231 | E209: 0.010365468 | F209: 23561726
A210: Global | B210: =$B$1+E210 | C210: 0.0093761768 | D210: 0.25367576 | E210: 0.013957073 | F210: 1.0759029e+08
B213: ERP | C213: Default Spread | D213: Tax rate | E213: CRP
A214: Africa & Mid East | B214: =$B$1+E214 | C214: 0.028036085 | D214: 0.20587211 | E214: =C214*1.52
